Workbook

Sheet Introduction
B2: Introduction & Information
A5: All previous financial data were taked from Intel Annual Reports (Income Statement & Balance Sheet & Cash Flow) - All publicly available
A7: Purpose of creating this model is purely for personal development & practice & curiosity - All forecasted numbers are based on personal analysis & opinion
A9: MODEL AND FINANCIAL DATA DO NOT CONTAIN ANY SENSITIVE DATA & FINANCIAL ADVICE
A11: Please do not publish the model anywhere. But if you are interested in using or developing the model for your personal development & curiosity, feel free
A13: If you`d like to discuss the model or have any questions about assumptions & formulas, please contact me
A15: Enjoy Exploring!
A17: Best Regards,
A18: Berk Tansuker
A20: Github
A21: LinkedIn
A22: E-Mail

Sheet Historical P&L
A1: Years Ended | B1: 2021 | C1: 2022 | D1: 2023 | E1: 2024 | F1: 2025
A2: Net revenue | B2: 79024 | C2: 63054 | D2: 54228 | E2: 53101 | F2: 52853
A3: Cost of sales | B3: 35209 | C3: 36188 | D3: 32517 | E3: 35756 | F3: 34478
A4: Gross profit | B4: 43815 | C4: 26866 | D4: 21711 | E4: 17345 | F4: 18375
A5: Research and development | B5: 15190 | C5: 17528 | D5: 16046 | E5: 16546 | F5: 13774
A6: Marketing, general and administrative | B6: 6543 | C6: 7002 | D6: 5634 | E6: 5507 | F6: 4624
A7: Restructuring and other charges | B7: 2626 | C7: 2 | D7: -62 | E7: 6970 | F7: 2191
A8: Operating expenses | B8: 24359 | C8: 24532 | D8: 21618 | E8: 29023 | F8: 20589
A9: Operating income (loss) | B9: 19456 | C9: 2334 | D9: 93 | E9: -11678 | F9: -2214
A10: Gains (losses) on equity investments, net | B10: 2729 | C10: 4268 | D10: 40 | E10: 242 | F10: 514
A11: Interest and other, net | B11: -482 | C11: 1166 | D11: 629 | E11: 226 | F11: 3257
A12: Income (loss) before taxes | B12: 21703 | C12: 7768 | D12: 762 | E12: -11210 | F12: 1557
... A20: Weighted average shares of common stock outstanding — Diluted | B20: 4090 | C20: 4123 | D20: 4212 | E20: 4280 | F20: 4530

Sheet Historical Balance Sheet
A1: Years Ended | B1: Dec 25, 2021 | C1: Dec 31, 2022 | D1: Dec 30, 2023 | E1: Dec 28, 2024 | F1: Dec 27, 2025
A2: Assets
A3: Cash and cash equivalents | B3: 4827 | C3: 11144 | D3: 7079 | E3: 8249 | F3: 14265
A4: Short-term investments | B4: 23586 | C4: 17194 | D4: 17955 | E4: 13813 | F4: 23151
A5: Accounts receivable, net | B5: 9457 | C5: 4133 | D5: 3402 | E5: 3478 | F5: 3839
A6: Inventories | B6: 10776 | C6: 13224 | D6: 11127 | E6: 12198 | F6: 11618
A7: Assets held for sale | B7: 6942 | C7: 0 | D7: 0 | E7: 0 | F7: 0
A8: Other current assets | B8: 2130 | C8: 4712 | D8: 3706 | E8: 9586 | F8: 10815
A9: Total current assets | B9: 57718 | C9: 50407 | D9: 43269 | E9: 47324 | F9: 63688
A10: Property, plant and equipment, net | B10: 63245 | C10: 80860 | D10: 96647 | E10: 107919 | F10: 105414
A11: Equity investments | B11: 6298 | C11: 5912 | D11: 5829 | E11: 5383 | F11: 8512
A12: Goodwill | B12: 26963 | C12: 27591 | D12: 27591 | E12: 24693 | F12: 23912
A13: Identified intangible assets, net | B13: 7270 | C13: 6018 | D13: 4589 | E13: 3691 | F13: 2772
A14: Other long-term assets | B14: 6912 | C14: 11315 | D14: 13647 | E14: 7475 | F14: 7131
A15: Total assets | B15: 168406 | C15: 182103 | D15: 191572 | E15: 196485 | F15: 211429
A16: Liabilities and stockholders' equity
A17: Short-term debt | B17: 4591 | C17: 4367 | D17: 2288 | E17: 3729 | F17: 2499
A18: Accounts payable | B18: 5747 | C18: 9595 | D18: 8578 | E18: 12556 | F18: 9882
A19: Accrued compensation and benefits | B19: 4535 | C19: 4084 | D19: 3655 | E19: 3343 | F19: 3990
A20: Income taxes payable | B20: 0 | C20: 2251 | D20: 1107 | E20: 1756 | F20: 604
A21: Other accrued liabilities | B21: 12589 | C21: 11858 | D21: 12425 | E21: 14282 | F21: 14600
A22: Total current liabilities | B22: 27462 | C22: 32155 | D22: 28053 | E22: 35666 | F22: 31575
A23: Debt | B23: 33510 | C23: 37684 | D23: 46978 | E23: 46282 | F23: 44086
A24: Long-term income taxes payable | B24: 4305 | C24: 0 | D24: 0 | E24: 0 | F24: 0
A25: Deferred income tax | B25: 2667 | C25: 0 | D25: 0 | E25: 0 | F25: 0
A26: Other long-term liabilities | B26: 5071 | C26: 8978 | D26: 6576 | E26: 9505 | F26: 9408
A27: Total liabilities | B27: 73015 | C27: 78817 | D27: 81607 | E27: 91453 | F27: 85069
A28: Common stock and additional paid-in capital | B28: 28006 | C28: 31580 | D28: 36649 | E28: 50949 | F28: 65185
... A34: Total liabilities and stockholders' equity | B34: 168406 | C34: 182103 | D34: 191572 | E34: 196485 | F34: 211429

Sheet Historical Cash Flow
A1: Years Ended | B1: Dec 25, 2021 | C1: Dec 31, 2022 | D1: Dec 30, 2023 | E1: Dec 28, 2024 | F1: Dec 27, 2025
A2: Cash and cash equivalents, beginning of period | B2: 5865 | C2: 4827 | D2: 11144 | E2: 7079 | F2: 8249
A3: Cash flows provided by (used for) operating activities:
A4: Net income (loss) | B4: 19868 | C4: 8017 | D4: 1675 | E4: -19233 | F4: 26
A5: Depreciation | B5: 9953 | C5: 11128 | D5: 7847 | E5: 9951 | F5: 10757
A6: Share-based compensation | B6: 2036 | C6: 3128 | D6: 3229 | E6: 3410 | F6: 2434
A7: Restructuring and other charges | B7: 2626 | C7: 1074 | D7: -424 | E7: 3491 | F7: 476
A8: Amortization of intangibles | B8: 1839 | C8: 1907 | D8: 1755 | E8: 1428 | F8: 949
A9: (Gains) losses on equity investments, net | B9: -1458 | C9: -4254 | D9: -42 | E9: -246 | F9: -514
A10: (Gains) losses on divestitures | B10: 0 | C10: -1059 | D10: 0 | E10: 0 | F10: -5323
A11: Mark-to-market (gains) losses on Escrowed Shares | B11: 0 | C11: 0 | D11: 0 | E11: 0 | F11: 1796
A12: Deferred taxes | B12: 0 | C12: 0 | D12: -2033 | E12: 6132 | F12: 328
A13: Impairments and net (gain) loss on retirement of property, plant and equipment | B13: 0 | C13: 0 | D13: 33 | E13: 2252 | F13: 515
A14: Accounts receivable | B14: -2674 | C14: 5327 | D14: 731 | E14: -75 | F14: -449
A15: Inventories | B15: -2339 | C15: -2436 | D15: 2097 | E15: -1105 | F15: -138
... A22: Net cash provided by operating activities | B22: 29456 | C22: 15433 | D22: 11471 | E22: 8288 | F22: 9697
A23: Cash flows provided by (used for) investing activities:
A24: Additions to property, plant and equipment | B24: -18733 | C24: -24844 | D24: -25750 | E24: -23944 | F24: -14646
A25: Additions to held for sale NAND property, plant and equipment | B25: -1596 | C25: -206 | D25: 0 | E25: 0 | F25: 0
A26: Proceeds from capital-related government incentives | B26: 166 | C26: 246 | D26: 1011 | E26: 1936 | F26: 1577
A27: Purchases of short-term investments | B27: -40554 | C27: -43647 | D27: -44414 | E27: -37940 | F27: -24319
A28: Maturities and sales of short-term investments | B28: 35299 | C28: 48730 | D28: 44077 | E28: 41463 | F28: 15387
A29: Purchases of equity investments | B29: -613 | C29: -510 | D29: 0 | E29: 0 | F29: 0
A30: Sales of equity investments | B30: 581 | C30: 4961 | D30: 472 | E30: 1047 | F30: 671
A31: Proceeds from divestitures, net | B31: 0 | C31: 6579 | D31: 0 | E31: 0 | F31: 6157
A32: Other investing | B32: 1167 | C32: -1540 | D32: 563 | E32: -818 | F32: 352
A33: Net cash used for investing activities | B33: -24283 | C33: -10231 | D33: -24041 | E33: -18256 | F33: -14821
A34: Cash flows provided by (used for) financing activities:
A35: Issuance of commercial paper, net of issuance costs | B35: 0 | C35: 3945 | D35: 0 | E35: 7349 | F35: 3493
A36: Repayment of commercial paper | B36: 0 | C36: 0 | D36: -3944 | E36: -7349 | F36: -3493
A37: Payments on finance leases | B37: 0 | C37: -345 | D37: 0 | E37: 0 | F37: 0
A38: Partner contributions | B38: 0 | C38: 874 | D38: 1511 | E38: 12714 | F38: 5108
A39: Net proceeds from sales of subsidiary shares | B39: 0 | C39: 1032 | D39: 2959 | E39: 0 | F39: 921
A40: Additions to property, plant and equipment | B40: 0 | C40: 0 | D40: 0 | E40: -1178 | F40: -3026
A41: Issuance of long-term debt, net of issuance costs | B41: 4974 | C41: 6548 | D41: 11391 | E41: 2975 | F41: 0
A42: Repayment of debt | B42: -2500 | C42: -4984 | D42: -423 | E42: -2288 | F42: -3750
A43: Proceeds from sales of common stock through employee equity incentive plans | B43: 1020 | C43: 977 | D43: 1042 | E43: 987 | F43: 771
A44: Net proceeds attributable to common stock and warrants issued, and Escrowed Shares | B44: 0 | C44: 0 | D44: 0 | E44: 0 | F44: 12706
A45: Repurchase of common stock | B45: -2415 | C45: 0 | D45: 0 | E45: 0 | F45: 0
A46: Restricted stock unit withholdings | B46: 0 | C46: 0 | D46: -534 | E46: -631 | F46: -423
...

Sheet Financial Model & Forecast
C1: Historical Results | H1: Forecast Period
C2: 2021 | D2: 2022 | E2: 2023 | F2: 2024 | G2: 2025 | H2: 2026 | I2: 2027 | J2: 2028 | K2: 2029 | L2: 2030
A3: Balance Sheet Check | C3: =IFERROR(IF(ABS(C69)>1,"ERROR","OK"),"OK") -> OK | D3: =IFERROR(IF(ABS(D69)>1,"ERROR","OK"),"OK") -> OK | E3: =IFERROR(IF(ABS(E69)>1,"ERROR","OK"),"OK") -> OK | F3: =IFERROR(IF(ABS(F69)>1,"ERROR","OK"),"OK") -> OK | G3: =IFERROR(IF(ABS(G69)>1,"ERROR","OK"),"OK") -> OK | H3: =IFERROR(IF(ABS(H69)>1,"ERROR","OK"),"OK") -> OK | I3: =IFERROR(IF(ABS(I69)>1,"ERROR","OK"),"OK") -> OK | J3: =IFERROR(IF(ABS(J69)>1,"ERROR","OK"),"OK") -> OK | ... L3: =IFERROR(IF(ABS(L69)>1,"ERROR","OK"),"OK") -> OK
C4: Scenario
C5: Base
A7: Assumptions | C7: 2021 | D7: 2022 | E7: 2023 | F7: 2024 | G7: 2025 | H7: 2026 | I7: 2027 | J7: 2028 | K7: 2029 | L7: 2030
A9: Key Assumptions
A10: Revenue Growth (% Change) | D10: =D29/C29-1 -> -0.2020905 | E10: =E29/D29-1 -> -0.13997526 | F10: =F29/E29-1 -> -0.020782622 | G10: =G29/F29-1 -> -0.0046703452 | H10: =INDEX('Scenario Assumptions'!C2:E2,MATCH($C$5, 'Scenario Assumptions'!C$1:E$1, 0)) -> 0.03 | I10: =H10 -> 0.03 | J10: =I10 -> 0.03 | K10: =J10 -> 0.03 | L10: =K10 -> 0.03
A11: Gross Margin (%) | C11: =C31/C29 -> 0.55445181 | D11: =D31/D29 -> 0.42607923 | E11: =E31/E29 -> 0.40036513 | F11: =F31/F29 -> 0.32664168 | G11: =G31/G29 -> 0.34766238 | H11: 0.35 | I11: 0.36 | J11: 0.39 | K11: 0.4 | L11: 0.42
A12: SG&A (% of Revenue) | C12: =C33/C29 -> 0.082797631 | D12: =D33/D29 -> 0.11104767 | E12: =E33/E29 -> 0.10389467 | F12: =F33/F29 -> 0.10370803 | G12: =G33/G29 -> 0.087487938 | H12: 0.09 | I12: 0.09 | J12: 0.09 | K12: 0.09 | L12: 0.09
A13: Research and Development (% of Revenue) | C13: =C32/C29 -> 0.19222009 | D13: =D32/D29 -> 0.27798395 | E13: =E32/E29 -> 0.2958988 | F13: =F32/F29 -> 0.31159489 | G13: =G32/G29 -> 0.26060962 | H13: 0.27 | I13: 0.27 | J13: 0.27 | K13: 0.27 | L13: 0.27
A14: Restructuring & other charges (% of Revenue) | C14: =C34/C29 -> 0.033230411 | D14: =D34/D29 -> 3.1718844e-05 | E14: =E34/E29 -> -0.0011433208 | F14: =F34/F29 -> 0.1312593 | G14: =G34/G29 -> 0.0414546 | H14: 0.02 | I14: 0.02 | J14: 0.02 | K14: 0.02 | L14: 0.02
A15: Accounts Receivable (Days) | C15: =C49/C29*C24 -> 43.680464 | D15: =D49/D29*D24 -> 23.924652 | E15: =E49/E29*E24 -> 22.898318 | F15: =F49/F29*F24 -> 23.906706 | G15: =G49/G29*G24 -> 26.511929 | H15: 27 | I15: 26 | J15: 26 | K15: 25 | L15: 25
A16: Inventory (Days) | C16: =C50/C30*C24 -> 111.71121 | D16: =D50/D30*D24 -> 133.38013 | E16: =E50/E30*E24 -> 124.89944 | F16: =F50/F30*F24 -> 124.51812 | G16: =G50/G30*G24 -> 122.9935 | H16: 120 | I16: 118 | J16: 116 | K16: 115 | L16: 115
A17: Accounts Payable (Days) | C17: =C57/C30*C24 -> 59.577239 | D17: =D57/D30*D24 -> 96.777247 | E17: =E57/E30*E24 -> 96.287173 | F17: =F57/F30*F24 -> 128.17261 | G17: =G57/G30*G24 -> 104.61541 | H17: 100 | I17: 100 | J17: 100 | K17: 100 | L17: 100
A18: Capex (% of Revenue) | C18: =-C82/C29 -> 0.25725096 | D18: =-D82/D29 -> 0.39727852 | E18: =-E82/E29 -> 0.47484694 | F18: =-F82/F29 -> 0.4509143 | G18: =-G82/G29 -> 0.27710821 | H18: 0.3 | I18: 0.3 | J18: 0.3 | K18: 0.3 | L18: 0.3
A19: D&A (% of PPE) | C19: =C42/C52 -> 0.18644952 | D19: =D42/D52 -> 0.16120455 | E19: =E42/E52 -> 0.099351247 | F19: =F42/F52 -> 0.10544019 | G19: =G42/G52 -> 0.11104787 | H19: 0.11 | I19: 0.11 | J19: 0.11 | K19: 0.11 | L19: 0.11
A20: Provision (Benefit) Tax Rate (%) | C20: =C39/C38 -> 0.084550523 | D20: =D39/D38 -> -0.032054583 | E20: =E39/E38 -> -1.1981627 | F20: =F39/F38 -> -0.71570027 | G20: =G39/G38 -> 0.98330122 | H20: 0.2 | I20: 0.2 | J20: 0.2 | K20: 0.2 | L20: 0.2
A21: Dividend Payout Ratio (%) | C21: =-C87/C40 -> 0.28407489 | D21: =-D87/D40 -> 0.74803542 | E21: =-E87/E40 -> 1.8435821 | F21: =-F87/F40 -> -0.083138356 | G21: =-G87/G40 -> 0 | H21: 0.25 | I21: 0.25 | J21: 0.25 | K21: 0.25 | L21: 0.25
A22: Debt Issuance (Repayment) | C22: =C86 -> 2474 | D22: =D86 -> 5509 | E22: =E86 -> 7024 | F22: =F86 -> 687 | G22: =G86 -> -3750 | H22: -1000 | I22: -1000 | J22: -1000 | K22: -1000 | L22: -1000
A23: Interest & other (net) (% of Revenue) | C23: =C37/C29 -> 0.0284344 | D23: =D37/D29 -> 0.0861801 | E23: =E37/E29 -> 0.0123368 | F23: =F37/F29 -> 0.0088133933 | G23: =G37/G29 -> 0.071348835 | H23: 0.05 | I23: 0.05 | J23: 0.05 | K23: 0.05 | L23: 0.05
A24: Days in Period | C24: 365 | D24: 365 | E24: 365 | F24: 365 | G24: 365 | H24: 365 | I24: 365 | J24: 365 | K24: 365 | L24: 365
A27: Income Statement | C27: 2021 | D27: 2022 | E27: 2023 | F27: 2024 | G27: 2025 | H27: 2026 | I27: 2027 | J27: 2028 | K27: 2029 | L27: 2030
A29: Net Revenue | C29: ='Historical P&L'!B2 -> 79024 | D29: ='Historical P&L'!C2 -> 63054 | E29: ='Historical P&L'!D2 -> 54228 | F29: ='Historical P&L'!E2 -> 53101 | G29: ='Historical P&L'!F2 -> 52853 | H29: =G29*(1+H10) -> 54438.59 | I29: =H29*(1+I10) -> 56071.748 | J29: =I29*(1+J10) -> 57753.9 | K29: =J29*(1+K10) -> 59486.517 | L29: =K29*(1+L10) -> 61271.113
A30: Cost of Revenue | C30: ='Historical P&L'!B3 -> 35209 | D30: ='Historical P&L'!C3 -> 36188 | E30: ='Historical P&L'!D3 -> 32517 | F30: ='Historical P&L'!E3 -> 35756 | G30: ='Historical P&L'!F3 -> 34478 | H30: =H29*(1-H11) -> 35385.084 | I30: =I29*(1-I11) -> 35885.919 | J30: =J29*(1-J11) -> 35229.879 | K30: =K29*(1-K11) -> 35691.91 | L30: =L29*(1-L11) -> 35537.245
A31: Gross profit | C31: =C29-C30 -> 43815 | D31: =D29-D30 -> 26866 | E31: =E29-E30 -> 21711 | F31: =F29-F30 -> 17345 | G31: =G29-G30 -> 18375 | H31: =H29-H30 -> 19053.507 | I31: =I29-I30 -> 20185.829 | J31: =J29-J30 -> 22524.021 | ... L31: =L29-L30 -> 25733.867
A32: Research & Development | C32: ='Historical P&L'!B5 -> 15190 | D32: ='Historical P&L'!C5 -> 17528 | E32: ='Historical P&L'!D5 -> 16046 | F32: ='Historical P&L'!E5 -> 16546 | G32: ='Historical P&L'!F5 -> 13774 | H32: =H29*H13 -> 14698.419 | I32: =I29*I13 -> 15139.372 | J32: =J29*J13 -> 15593.553 | K32: =K29*K13 -> 16061.36 | L32: =L29*L13 -> 16543.2
A33: SG&A | C33: ='Historical P&L'!B6 -> 6543 | D33: ='Historical P&L'!C6 -> 7002 | E33: ='Historical P&L'!D6 -> 5634 | F33: ='Historical P&L'!E6 -> 5507 | G33: ='Historical P&L'!F6 -> 4624 | H33: =H29*H12 -> 4899.4731 | I33: =I29*I12 -> 5046.4573 | J33: =J29*J12 -> 5197.851 | K33: =K29*K12 -> 5353.7865 | L33: =L29*L12 -> 5514.4001
A34: Restructuring and other charges | C34: ='Historical P&L'!B7 -> 2626 | D34: ='Historical P&L'!C7 -> 2 | E34: ='Historical P&L'!D7 -> -62 | F34: ='Historical P&L'!E7 -> 6970 | G34: ='Historical P&L'!F7 -> 2191 | H34: =H29*H14 -> 1088.7718 | I34: =I29*I14 -> 1121.435 | J34: =J29*J14 -> 1155.078 | K34: =K29*K14 -> 1189.7303 | L34: =L29*L14 -> 1225.4223
A35: Total Operating Expenses | C35: =SUM(C32:C34) -> 24359 | D35: =SUM(D32:D34) -> 24532 | E35: =SUM(E32:E34) -> 21618 | F35: =SUM(F32:F34) -> 29023 | G35: =SUM(G32:G34) -> 20589 | H35: =SUM(H32:H34) -> 20686.664 | I35: =SUM(I32:I34) -> 21307.264 | J35: =SUM(J32:J34) -> 21946.482 | ... L35: =SUM(L32:L34) -> 23283.023
A36: EBIT (Operating Income) | C36: =C31-C35 -> 19456 | D36: =D31-D35 -> 2334 | E36: =E31-E35 -> 93 | F36: =F31-F35 -> -11678 | G36: =G31-G35 -> -2214 | H36: =H31-H35 -> -1633.1577 | I36: =I31-I35 -> -1121.435 | J36: =J31-J35 -> 577.539 | ... L36: =L31-L35 -> 2450.8445
A37: Interest & Other (net) | C37: ='Historical P&L'!B10+'Historical P&L'!B11 -> 2247 | D37: ='Historical P&L'!C10+'Historical P&L'!C11 -> 5434 | E37: ='Historical P&L'!D10+'Historical P&L'!D11 -> 669 | F37: ='Historical P&L'!E10+'Historical P&L'!E11 -> 468 | G37: ='Historical P&L'!F10+'Historical P&L'!F11 -> 3771 | H37: =H29*H23 -> 2721.9295 | I37: =I29*I23 -> 2803.5874 | J37: =J29*J23 -> 2887.695 | K37: =K29*K23 -> 2974.3259 | L37: =L29*L23 -> 3063.5556
A38: EBT | C38: =SUM(C36:C37) -> 21703 | D38: =SUM(D36:D37) -> 7768 | E38: =SUM(E36:E37) -> 762 | F38: =SUM(F36:F37) -> -11210 | G38: =SUM(G36:G37) -> 1557 | H38: =SUM(H36:H37) -> 1088.7718 | I38: =SUM(I36:I37) -> 1682.1524 | J38: =SUM(J36:J37) -> 3465.234 | ... L38: =SUM(L36:L37) -> 5514.4001
A39: Provision for (benefit from) taxes | C39: ='Historical P&L'!B13 -> 1835 | D39: ='Historical P&L'!C13 -> -249 | E39: ='Historical P&L'!D13 -> -913 | F39: ='Historical P&L'!E13 -> 8023 | G39: ='Historical P&L'!F13 -> 1531 | H39: =H38*H20 -> 217.75436 | I39: =I38*I20 -> 336.43049 | J39: =J38*J20 -> 693.0468 | K39: =K38*K20 -> 832.81124 | L39: =L38*L20 -> 1102.88
A40: Net Income | C40: =C38-C39 -> 19868 | D40: =D38-D39 -> 8017 | E40: =E38-E39 -> 1675 | F40: =F38-F39 -> -19233 | G40: =G38-G39 -> 26 | H40: =H38-H39 -> 871.01744 | I40: =I38-I39 -> 1345.7219 | J40: =J38-J39 -> 2772.1872 | ... L40: =L38-L39 -> 4411.5201
A42: Model Helper (Cross - Statement) D&A (from CF) | C42: =C74 -> 11792 | D42: =D74 -> 13035 | E42: =E74 -> 9602 | F42: =F74 -> 11379 | G42: =G74 -> 11706 | H42: =H74 -> 11595.54 | I42: =I74 -> 12116.504 | J42: =J74 -> 12634.056 | ... L42: =L74 -> 13666.723
A43: EBITDA | C43: =C42+C36 -> 31248 | D43: =D42+D36 -> 15369 | E43: =E42+E36 -> 9695 | F43: =F42+F36 -> -299 | G43: =G42+G36 -> 9492 | H43: =H42+H36 -> 9962.3823 | I43: =I42+I36 -> 10995.069 | J43: =J42+J36 -> 13211.595 | ... L43: =L42+L36 -> 16117.568
A45: Balance Sheet | C45: 2021 | D45: 2022 | E45: 2023 | F45: 2024 | G45: 2025 | H45: 2026 | I45: 2027 | J45: 2028 | K45: 2029 | L45: 2030
A47: Assets
A48: Cash & Cash Equivalents | C48: ='Historical Balance Sheet'!B3 -> 4827 | D48: ='Historical Balance Sheet'!C3 -> 11144 | E48: ='Historical Balance Sheet'!D3 -> 7079 | F48: ='Historical Balance Sheet'!E3 -> 8249 | G48: ='Historical Balance Sheet'!F3 -> 14265 | H48: =H93 -> 24575.353 | I48: =I93 -> 35418.629 | J48: =J93 -> 47248.224 | K48: =K93 -> 59504.982 | L48: =L93 -> 72320.134
...

Sheet Scenario Assumptions
A1: Assumption Category | B1: Assumption Name | C1: Base | D1: Bull | E1: Bear
A2: Income Statement | B2: Revenue Growth (%) | C2: 0.03 | D2: 0.06 | E2: -0.01
